<?xml version="1.0" encoding="utf-8"?>
<!-- =================================================================================== -->
<!-- |    This document was autogenerated by xacro from rubot_mecanum.xacro            | -->
<!-- |    EDITING THIS FILE BY HAND IS NOT RECOMMENDED                                 | -->
<!-- =================================================================================== -->
<robot name="nexus">
  <material name="yellow">
    <color rgba="0.8 0.8 0.0 1.0"/>
  </material>
  <material name="black">
    <color rgba="0.15 0.15 0.15 1.0"/>
  </material>
  <material name="dark_grey">
    <color rgba="0.2 0.2 0.2 1.0"/>
  </material>
  <material name="light_grey">
    <color rgba="0.4 0.4 0.4 1.0"/>
  </material>
  <link name="base_footprint"/>
  <joint name="base_link_joint" type="fixed">
    <origin rpy="0 0 0" xyz="0 0 0.05"/>
    <parent link="base_footprint"/>
    <child link="base_link"/>
  </joint>
  <link name="base_link">
    <visual>
      <origin rpy="0 0 0" xyz="0 0 0"/>
      <geometry>
        <mesh filename="package://nexus_mecanum/meshes/nexus_base_link.STL" scale="0.001 0.001 0.001"/>
      </geometry>
      <material name="yellow"/>
    </visual>
    <collision>
      <origin xyz="0 0 0"/>
      <geometry>
        <mesh filename="package://nexus_mecanum/meshes/nexus_base_link_collision.STL" scale="0.001 0.001 0.001"/>
      </geometry>
    </collision>
    <inertial>
      <!-- Inertia from CAD model, filled box assumption -->
      <origin rpy="0 0 0" xyz="-0.01103 0 0.002"/>
      <mass value="2.844"/>
      <inertia ixx="0.018819942" ixy="0" ixz="-0.000101519" iyy="0.057333716" iyz="0" izz="0.074201740"/>
    </inertial>
  </link>
  <joint name="upper_left_wheel_shaft_joint" type="fixed">
    <origin rpy="0 0 0" xyz="0.150 0.108 0.0"/>
    <parent link="base_link"/>
    <child link="upper_left_wheel_shaft"/>
  </joint>
  <link name="upper_left_wheel_shaft">
    <visual>
      <origin rpy="0 0 0" xyz="0 0 0"/>
      <geometry>
        <mesh filename="package://nexus_mecanum/meshes/wheel_shaft.STL" scale="0.001 0.001 0.001"/>
      </geometry>
      <material name="black"/>
    </visual>
    <collision>
      <origin xyz="0 0 0"/>
      <geometry>
        <mesh filename="package://nexus_mecanum/meshes/wheel_shaft.STL" scale="0.001 0.001 0.001"/>
      </geometry>
    </collision>
    <inertial>
      <origin rpy="0 0 0" xyz="0 0.01221 0"/>
      <mass value="0.055"/>
      <inertia ixx="0.000021370" ixy="0" ixz="0" iyy="0.000009966" iyz="0" izz="0.000021370"/>
    </inertial>
  </link>
  <joint name="lower_left_wheel_shaft_joint" type="fixed">
    <origin rpy="0 0 0" xyz="-0.150 0.108 0.0"/>
    <parent link="base_link"/>
    <child link="lower_left_wheel_shaft"/>
  </joint>
  <link name="lower_left_wheel_shaft">
    <visual>
      <origin rpy="0 0 0" xyz="0 0 0"/>
      <geometry>
        <mesh filename="package://nexus_mecanum/meshes/wheel_shaft.STL" scale="0.001 0.001 0.001"/>
      </geometry>
      <material name="black"/>
    </visual>
    <collision>
      <origin xyz="0 0 0"/>
      <geometry>
        <mesh filename="package://nexus_mecanum/meshes/wheel_shaft.STL" scale="0.001 0.001 0.001"/>
      </geometry>
    </collision>
    <inertial>
      <origin rpy="0 0 0" xyz="0 0.01221 0"/>
      <mass value="0.055"/>
      <inertia ixx="0.000021370" ixy="0" ixz="0" iyy="0.000009966" iyz="0" izz="0.000021370"/>
    </inertial>
  </link>
  <joint name="upper_right_wheel_shaft_joint" type="fixed">
    <origin rpy="3.14159265359 0 0" xyz="0.150 -0.108 0.0"/>
    <parent link="base_link"/>
    <child link="upper_right_wheel_shaft"/>
  </joint>
  <link name="upper_right_wheel_shaft">
    <visual>
      <origin rpy="0 0 0" xyz="0 0 0"/>
      <geometry>
        <mesh filename="package://nexus_mecanum/meshes/wheel_shaft.STL" scale="0.001 0.001 0.001"/>
      </geometry>
      <material name="black"/>
    </visual>
    <collision>
      <origin xyz="0 0 0"/>
      <geometry>
        <mesh filename="package://nexus_mecanum/meshes/wheel_shaft.STL" scale="0.001 0.001 0.001"/>
      </geometry>
    </collision>
    <inertial>
      <origin rpy="0 0 0" xyz="0 0.01221 0"/>
      <mass value="0.055"/>
      <inertia ixx="0.000021370" ixy="0" ixz="0" iyy="0.000009966" iyz="0" izz="0.000021370"/>
    </inertial>
  </link>
  <joint name="lower_right_wheel_shaft_joint" type="fixed">
    <origin rpy="3.14159265359 0 0" xyz="-0.150 -0.108 0.0"/>
    <parent link="base_link"/>
    <child link="lower_right_wheel_shaft"/>
  </joint>
  <link name="lower_right_wheel_shaft">
    <visual>
      <origin rpy="0 0 0" xyz="0 0 0"/>
      <geometry>
        <mesh filename="package://nexus_mecanum/meshes/wheel_shaft.STL" scale="0.001 0.001 0.001"/>
      </geometry>
      <material name="black"/>
    </visual>
    <collision>
      <origin xyz="0 0 0"/>
      <geometry>
        <mesh filename="package://nexus_mecanum/meshes/wheel_shaft.STL" scale="0.001 0.001 0.001"/>
      </geometry>
    </collision>
    <inertial>
      <origin rpy="0 0 0" xyz="0 0.01221 0"/>
      <mass value="0.055"/>
      <inertia ixx="0.000021370" ixy="0" ixz="0" iyy="0.000009966" iyz="0" izz="0.000021370"/>
    </inertial>
  </link>
  <joint name="upper_left_wheel_joint" type="continuous">
    <origin rpy="0 0 0" xyz="0 0.042 0"/>
    <parent link="upper_left_wheel_shaft"/>
    <child link="upper_left_wheel"/>
    <axis xyz="0 1 0"/>
  </joint>
  <link name="upper_left_wheel">
    <visual>
      <origin rpy="0 0 0" xyz="0 0 0"/>
      <geometry>
        <mesh filename="package://nexus_mecanum/meshes/mecanum_wheel_left.STL" scale="0.001 0.001 0.001"/>
      </geometry>
      <material name="light_grey"/>
    </visual>
    <collision>
      <origin rpy="1.57079632679 0 0" xyz="0 0 0"/>
      <geometry>
        <cylinder length="0.0505" radius="0.05"/>
      </geometry>
    </collision>
    <inertial>
      <origin rpy="0 0 0" xyz="0.0 0.0 0.0"/>
      <mass value="0.3844"/>
      <!-- Inertia based on cylinder -->
      <inertia ixx="0.000324824" ixy="0" ixz="0" iyy="0.000480000" iyz="0" izz="0.000324824"/>
    </inertial>
  </link>
  <joint name="lower_left_wheel_joint" type="continuous">
    <origin rpy="0 0 0" xyz="0 0.042 0"/>
    <parent link="lower_left_wheel_shaft"/>
    <child link="lower_left_wheel"/>
    <axis xyz="0 1 0"/>
  </joint>
  <link name="lower_left_wheel">
    <visual>
      <origin rpy="0 0 0" xyz="0 0 0"/>
      <geometry>
        <mesh filename="package://nexus_mecanum/meshes/mecanum_wheel_right.STL" scale="0.001 0.001 0.001"/>
      </geometry>
      <material name="light_grey"/>
    </visual>
    <collision>
      <origin rpy="1.57079632679 0 0" xyz="0 0 0"/>
      <geometry>
        <cylinder length="0.0505" radius="0.05"/>
      </geometry>
    </collision>
    <inertial>
      <origin rpy="0 0 0" xyz="0.0 0.0 0.0"/>
      <mass value="0.3844"/>
      <!-- Inertia based on cylinder -->
      <inertia ixx="0.000324824" ixy="0" ixz="0" iyy="0.000480000" iyz="0" izz="0.000324824"/>
    </inertial>
  </link>
  <joint name="upper_right_wheel_joint" type="continuous">
    <origin rpy="0 0 0" xyz="0 0.042 0"/>
    <parent link="upper_right_wheel_shaft"/>
    <child link="upper_right_wheel"/>
    <axis xyz="0 1 0"/>
  </joint>
  <link name="upper_right_wheel">
    <visual>
      <origin rpy="0 0 0" xyz="0 0 0"/>
      <geometry>
        <mesh filename="package://nexus_mecanum/meshes/mecanum_wheel_right.STL" scale="0.001 0.001 0.001"/>
      </geometry>
      <material name="light_grey"/>
    </visual>
    <collision>
      <origin rpy="1.57079632679 0 0" xyz="0 0 0"/>
      <geometry>
        <cylinder length="0.0505" radius="0.05"/>
      </geometry>
    </collision>
    <inertial>
      <origin rpy="0 0 0" xyz="0.0 0.0 0.0"/>
      <mass value="0.3844"/>
      <!-- Inertia based on cylinder -->
      <inertia ixx="0.000324824" ixy="0" ixz="0" iyy="0.000480000" iyz="0" izz="0.000324824"/>
    </inertial>
  </link>
  <joint name="lower_right_wheel_joint" type="continuous">
    <origin rpy="0 0 0" xyz="0 0.042 0"/>
    <parent link="lower_right_wheel_shaft"/>
    <child link="lower_right_wheel"/>
    <axis xyz="0 1 0"/>
  </joint>
  <link name="lower_right_wheel">
    <visual>
      <origin rpy="0 0 0" xyz="0 0 0"/>
      <geometry>
        <mesh filename="package://nexus_mecanum/meshes/mecanum_wheel_left.STL" scale="0.001 0.001 0.001"/>
      </geometry>
      <material name="light_grey"/>
    </visual>
    <collision>
      <origin rpy="1.57079632679 0 0" xyz="0 0 0"/>
      <geometry>
        <cylinder length="0.0505" radius="0.05"/>
      </geometry>
    </collision>
    <inertial>
      <origin rpy="0 0 0" xyz="0.0 0.0 0.0"/>
      <mass value="0.3844"/>
      <!-- Inertia based on cylinder -->
      <inertia ixx="0.000324824" ixy="0" ixz="0" iyy="0.000480000" iyz="0" izz="0.000324824"/>
    </inertial>
  </link>
  <joint name="left_sensor_joint" type="fixed">
    <origin rpy="0 0 1.57079632679" xyz="0 0.108 0.010"/>
    <parent link="base_link"/>
    <child link="left_sensor"/>
  </joint>
  <link name="left_sensor">
    <visual>
      <origin rpy="1.57079632679 0 0" xyz="0 0 0"/>
      <geometry>
        <mesh filename="package://nexus_mecanum/meshes/urm04.STL" scale="0.001 0.001 0.001"/>
      </geometry>
      <material name="black"/>
    </visual>
  </link>
  <joint name="front_sensor_joint" type="fixed">
    <origin rpy="0 0 0" xyz="0.205 0 0.010"/>
    <parent link="base_link"/>
    <child link="front_sensor"/>
  </joint>
  <link name="front_sensor">
    <visual>
      <origin rpy="1.57079632679 0 0" xyz="0 0 0"/>
      <geometry>
        <mesh filename="package://nexus_mecanum/meshes/urm04.STL" scale="0.001 0.001 0.001"/>
      </geometry>
      <material name="black"/>
    </visual>
  </link>
  <joint name="right_sensor_joint" type="fixed">
    <origin rpy="0 0 -1.57079632679" xyz="0 -0.108 0.010"/>
    <parent link="base_link"/>
    <child link="right_sensor"/>
  </joint>
  <link name="right_sensor">
    <visual>
      <origin rpy="1.57079632679 0 0" xyz="0 0 0"/>
      <geometry>
        <mesh filename="package://nexus_mecanum/meshes/urm04.STL" scale="0.001 0.001 0.001"/>
      </geometry>
      <material name="black"/>
    </visual>
  </link>
  <joint name="rear_sensor_joint" type="fixed">
    <origin rpy="0 0 3.14159265359" xyz="-0.201 0 0.010"/>
    <parent link="base_link"/>
    <child link="rear_sensor"/>
  </joint>
  <link name="rear_sensor">
    <visual>
      <origin rpy="1.57079632679 0 0" xyz="0 0 0"/>
      <geometry>
        <mesh filename="package://nexus_mecanum/meshes/urm04.STL" scale="0.001 0.001 0.001"/>
      </geometry>
      <material name="black"/>
    </visual>
  </link>
  <!-- 2D Camera as a mesh of actual PiCamera -->
  <link name="camera">
    <visual>
      <origin rpy="0 1.570795 0" xyz="0 0 0"/>
      <geometry>
        <mesh filename="package://nexus_mecanum/meshes/piCamera.stl" scale="0.0025 0.0025 0.0025"/>
      </geometry>
      <material name="yellow"/>
    </visual>
    <collision>
      <origin rpy="0 1.570795 0" xyz="0 0 0"/>
      <geometry>
        <box size="0.075 0.075 0.025"/>
      </geometry>
    </collision>
    <inertial>
      <origin rpy="0 1.570795 0" xyz="0 0 0"/>
      <mass value="1e-3"/>
      <inertia ixx="1e-6" ixy="0" ixz="0" iyy="1e-6" iyz="0" izz="1e-6"/>
    </inertial>
  </link>
  <!-- 2D Camera JOINT base_link -->
  <joint name="joint_camera" type="fixed">
    <axis xyz="0 0 1"/>
    <origin rpy="0 0 0" xyz="0.2 0 0.05"/>
    <parent link="base_link"/>
    <child link="camera"/>
  </joint>
  <!-- LIDAR base_scan -->
  <link name="base_scan">
    <visual name="sensor_body">
      <origin rpy="0 0 3.1415" xyz="0 0 0.04"/>
      <geometry>
        <mesh filename="package://nexus_mecanum/meshes/X4.stl" scale="0.0015 0.0015 0.0015"/>
      </geometry>
      <material name="yellow"/>
    </visual>
    <collision>
      <origin rpy="0 0 0" xyz="0 0 0.04"/>
      <geometry>
        <cylinder length="0.01575" radius="0.0275"/>
      </geometry>
    </collision>
    <inertial>
      <origin rpy="0 0 0" xyz="0 0 0.4"/>
      <mass value="0.057"/>
      <inertia ixx="0.001" ixy="0.0" ixz="0.0" iyy="0.001" iyz="0.0" izz="0.001"/>
    </inertial>
  </link>
  <!-- LIDAR base_scan JOINT base_link -->
  <joint name="scan_joint" type="fixed">
    <axis xyz="0 0 1"/>
    <origin rpy="0 0 0" xyz="0 0 0.09"/>
    <parent link="base_link"/>
    <child link="base_scan"/>
  </joint>
  <!-- Mecanum drive controller -->
  <gazebo>
    <plugin name="Mecanum_controller" filename="libgazebo_ros_planar_move.so">
      <commandTopic>cmd_vel</commandTopic>
      <odometryTopic>odom</odometryTopic>
      <odometryFrame>odom</odometryFrame>
      <odometryRate>50.0</odometryRate>
      <robotBaseFrame>base_footprint</robotBaseFrame>
    </plugin>
  </gazebo>
  <!-- 2D Camera controller -->
  <gazebo reference="camera">
    <sensor name="camera1" type="camera">
      <update_rate>30.0</update_rate>
      <camera name="front">
        <horizontal_fov>1.3962634</horizontal_fov>
        <image>
          <width>800</width>
          <height>800</height>
          <format>R8G8B8</format>
        </image>
        <clip>
          <near>0.02</near>
          <far>300</far>
        </clip>
      </camera>
      <plugin filename="libgazebo_ros_camera.so" name="camera_controller">
        <alwaysOn>true</alwaysOn>
        <updateRate>0.0</updateRate>
        <cameraName>rubot/camera1</cameraName>
        <imageTopicName>image_raw</imageTopicName>
        <cameraInfoTopicName>camera_info</cameraInfoTopicName>
        <frameName>camera</frameName>
        <hackBaseline>0.07</hackBaseline>
        <distortionK1>0.0</distortionK1>
        <distortionK2>0.0</distortionK2>
        <distortionK3>0.0</distortionK3>
        <distortionT1>0.0</distortionT1>
        <distortionT2>0.0</distortionT2>
      </plugin>
    </sensor>
  </gazebo>
  <!-- Laser Distance Sensor YDLIDAR X4 controller-->
  <gazebo reference="base_scan">
    <sensor name="lds_lfcd_sensor" type="ray">
      <pose>0 0 0 0 0 0</pose>
      <visualize>false</visualize>
      <update_rate>5</update_rate>
      <ray>
        <scan>
          <horizontal>
            <samples>720</samples>
            <resolution>1</resolution>
            <min_angle>0.0</min_angle>
            <max_angle>6.28319</max_angle>
          </horizontal>
        </scan>
        <range>
          <min>0.12</min>
          <max>10</max>
          <resolution>0.015</resolution>
        </range>
        <noise>
          <type>gaussian</type>
          <!-- Noise parameters based on published spec for YDLIDAR X4
              is 1.5% at half range 4m (= 60mm, "+-160mm" accuracy at max. range 8m).
              A mean of 0.0m and stddev of 0.020m will put 99.7% of samples
              within 0.16m of the true reading. -->
          <mean>0.0</mean>
          <stddev>0.02</stddev>
        </noise>
      </ray>
      <plugin filename="libgazebo_ros_laser.so" name="gazebo_ros_lds_lfcd_controller">
        <!-- topicName>/gopigo/scan</topicName -->
        <topicName>scan</topicName>
        <frameName>base_scan</frameName>
      </plugin>
    </sensor>
  </gazebo>
  <!-- All static links get collapsed down to base_link in Gazebo, so that's
       the one to apply the colour to (in Gazebo 5+). -->
  <gazebo reference="base_footprint">
    <material>Gazebo/Yellow</material>
    <gravity>true</gravity>
  </gazebo>
  <gazebo reference="base_link">
    <material>Gazebo/Yellow</material>
  </gazebo>
  <gazebo reference="base_scan">
    <material>Gazebo/Black</material>
  </gazebo>
  <gazebo reference="camera">
    <material>Gazebo/Black</material>
  </gazebo>
  <gazebo reference="left_sensor">
    <material>Gazebo/Black</material>
  </gazebo>
  <gazebo reference="front_sensor">
    <material>Gazebo/Black</material>
  </gazebo>
  <gazebo reference="right_sensor">
    <material>Gazebo/Black</material>
  </gazebo>
  <gazebo reference="rear_sensor">
    <material>Gazebo/Black</material>
  </gazebo>
  <gazebo reference="upper_left_wheel_shaft">
    <material>Gazebo/Black</material>
  </gazebo>
  <gazebo reference="lower_left_wheel_shaft">
    <material>Gazebo/Black</material>
  </gazebo>
  <gazebo reference="upper_right_wheel_shaft">
    <material>Gazebo/Black</material>
  </gazebo>
  <gazebo reference="lower_right_wheel_shaft">
    <material>Gazebo/Black</material>
  </gazebo>

</robot>
