<?xml version='1.0'?>
<robot name="gopigo3">

<!-- Materials -->
  <material name="blue">
    <color rgba="0 0 0.8 1"/>
  </material>

  <material name="white">
    <color rgba="1 1 1 1"/>
  </material>

  <material name="red">
    <color rgba="1 0 0 1"/>
  </material>

  <material name="green">
    <color rgba="0 1 0 1"/>
  </material>

  <material name="yellow">
    <color rgba="1 1 0 1"/>
  </material>

  <material name="orange">
    <color rgba="1 0.54 0 1"/>
  </material>

<!-- Base Link -->
  <link name="base_link">
    <visual>
      <origin xyz="-0.1 0.03 -0.038" rpy="0 0 1.57" />
      <geometry>
        <mesh filename="package://gopigo3_description/meshes/GoPiGo3_Body.stl" scale="0.001158 0.001158 0.001158"/>
      </geometry>
      <material name="blue"/>
    </visual>
    <collision>
      <origin xyz="0 0 0" rpy="0 0 0" />
      <geometry>
          <box size="0.5 0.25 0.125"/>
      </geometry>
    </collision>
    <inertial>
      <origin xyz="0 0 0" rpy="0 0 0" />
      <mass value="5"/>
      <inertia ixx="0.13" ixy="0.0" ixz="0.0" iyy="0.21" iyz="0.0" izz="0.13"/>
    </inertial>
  </link>
<!-- Right Wheel -->
  <link name="right_wheel">
    <visual>
      <origin xyz="-0.22581 -0.200334 -0.033582" rpy="0 0 0" />
      <geometry>
        <mesh filename="package://gopigo3_description/meshes/GoPiGo3_Wheel.stl" scale="0.001158 0.001158 0.001158"/>
      </geometry>
      <material name="orange"/>
    </visual>
    <!-- Right Wheel collision, mass and inertia -->
    <collision>
      <origin xyz="0 0 0" rpy="1.570795 0 0" />
      <geometry>
          <cylinder length="0.05" radius="0.1" />
      </geometry>
    </collision>
    <inertial>
      <origin xyz="0 0 0" rpy="1.570795 0 0" />
      <mass value="0.15"/>
      <inertia ixx="0.01" ixy="0.0" ixz="0.0" iyy="0.005" iyz="0.0" izz="0.005"/>
    </inertial>
  </link>
<!-- Right Wheel JOINT base_link -->
  <joint name="joint_right_wheel" type="continuous">
    <parent link="base_link"/>
    <child link="right_wheel"/>
    <origin xyz="0.012 -0.058 0.005" rpy="0 0 -1.57" /> 
    <axis xyz="1 0 0" />
  </joint>
<!-- Left Wheel JOINT base_link -->
  <joint name="joint_left_wheel" type="continuous">
    <parent link="base_link"/>
    <child link="left_wheel"/>
    <origin xyz="0.012 0.058 0.005" rpy="0 0 1.57" /> 
    <axis xyz="1 0 0"/>
  </joint>
<!-- Left Wheel -->
  <link name="left_wheel">
    <visual>
      <origin xyz="-0.22581 -0.200334 -0.033582" rpy="0 0 0" />
      <geometry>
        <mesh filename="package://gopigo3_description/meshes/GoPiGo3_Wheel.stl" scale="0.001158 0.001158 0.001158"/>
      </geometry>
      <material name="orange"/>
    </visual>
    <!-- Left Wheel collision, mass and inertia -->
    <collision>
      <origin xyz="0 0 0" rpy="1.570795 0 0" />
      <geometry>
          <cylinder length="0.05" radius="0.1" />
      </geometry>
    </collision>
    <inertial>
      <origin xyz="0 0 0" rpy="1.570795 0 0" />
      <mass value="0.15"/>
      <inertia ixx="0.01" ixy="0.0" ixz="0.0" iyy="0.005" iyz="0.0" izz="0.005"/>
    </inertial>
  </link>
<!-- 2D Camera as a mesh of actual PiCamera -->
  <link name="camera">
    <visual>
      <origin xyz="0 0 0" rpy="0 1.570795 0" />
      <geometry>
        <mesh filename="package://gopigo3_description/meshes/piCamera.stl" scale="0.001158 0.001158 0.001158"/>
      </geometry>
      <material name="yellow"/>
    </visual>
    
    <collision>
      <origin xyz="0 0 0" rpy="0 1.570795 0" />
      <geometry>
        <box size="0.075 0.075 0.025"/>
      </geometry>
    </collision>

    <inertial>
      <origin xyz="0 0 0" rpy="0 1.570795 0" />
      <mass value="1e-3" />
      <inertia ixx="1e-6" ixy="0" ixz="0" iyy="1e-6" iyz="0" izz="1e-6" />
    </inertial>
  </link>
<!-- 2D Camera JOINT base_link -->
  <joint name="joint_camera" type="fixed">
    <axis xyz="0 0 1" />
    <origin xyz="0.08 0 0.04" rpy="0 0 0"/>
    <parent link="base_link"/>
    <child link="camera"/>
  </joint>

<!-- LIDAR base_scan -->
  <link name="base_scan">
    <visual name="sensor_body">
      <origin xyz="0 0 0.04" rpy="0 0 0" />
      <geometry>
        <mesh filename="package://gopigo3_description/meshes/X4.stl" scale="0.001158 0.001158 0.001158"/> 
      </geometry>
      <material name="yellow"/>
    </visual>

    <collision>
      <origin xyz="0 0 0.04" rpy="0 0 0"/>
      <geometry>
        <cylinder length="0.01575" radius="0.0275"/>
      </geometry>
    </collision>

    <inertial>
      <origin xyz="0 0 0.4" rpy="0 0 0"/>
      <mass value="0.057" />
      <inertia ixx="0.001" ixy="0.0" ixz="0.0"
               iyy="0.001" iyz="0.0"
               izz="0.001" />
    </inertial>
  </link>
<!-- LIDAR base_scan JOINT base_link -->
  <joint name="scan_joint" type="fixed">
    <axis xyz="0 0 1" />
    <origin xyz="-0.01 0 0.11" rpy="0 0 0"/>
    <parent link="base_link"/>
    <child link="base_scan"/>
  </joint>

<!-- GAZEBO MATERIAL TAGS (colors for sensors under <sensor> tags) -->
  <gazebo reference="base_link">
    <material>Gazebo/Blue</material>
    <pose>0 0 1.5 0 0 0</pose>
  </gazebo>

  <gazebo reference="right_wheel">
    <material>Gazebo/White</material>
  </gazebo>

  <gazebo reference="left_wheel">
    <material>Gazebo/White</material>
  </gazebo>

<!-- Differential Drive Controller -->
  <!-- https://answers.ros.org/question/236122/diffdrive-odometry-source-is-missing -->
  <gazebo>
    <plugin filename="libgazebo_ros_diff_drive.so" name="differential_drive_controller">
      <alwaysOn>true</alwaysOn>
      <updateRate>20</updateRate>
      <leftJoint>joint_left_wheel</leftJoint>
      <rightJoint>joint_right_wheel</rightJoint>
      <wheelSeparation>0.25</wheelSeparation>
      <wheelDiameter>0.1</wheelDiameter>
      <torque>0.1</torque>
      <commandTopic>cmd_vel</commandTopic>
      <odometryTopic>odom</odometryTopic>
      <odometryFrame>odom</odometryFrame>
      <robotBaseFrame>base_link</robotBaseFrame>
      <odometrySource>1</odometrySource>
      <legacyMode>false</legacyMode>
      <publishTf>1</publishTf>
      <rosDebugLevel>na</rosDebugLevel>
      <publishWheelTF>false</publishWheelTF>
      <publishOdomTF>true</publishOdomTF>
      <publishWheelJointState>false</publishWheelJointState>
      <wheelAcceleration>0</wheelAcceleration>
      <wheelTorque>5</wheelTorque>
    </plugin>
  </gazebo>

<!-- 2D Camera controller -->
  <gazebo reference="camera">
    <sensor type="camera" name="camera1">
      <update_rate>30.0</update_rate>
      <camera name="front">
        <horizontal_fov>1.3962634</horizontal_fov>
        <image>
          <width>800</width>
          <height>800</height>
          <format>R8G8B8</format>
        </image>
        <clip>
          <near>0.02</near>
          <far>300</far>
        </clip>
      </camera>
      <plugin name="camera_controller" filename="libgazebo_ros_camera.so">
        <alwaysOn>true</alwaysOn>
        <updateRate>0.0</updateRate>
        <cameraName>gopigo/camera1</cameraName>
        <imageTopicName>image_raw</imageTopicName>
        <cameraInfoTopicName>camera_info</cameraInfoTopicName>
        <frameName>camera</frameName>
        <hackBaseline>0.07</hackBaseline>
        <distortionK1>0.0</distortionK1>
        <distortionK2>0.0</distortionK2>
        <distortionK3>0.0</distortionK3>
        <distortionT1>0.0</distortionT1>
        <distortionT2>0.0</distortionT2>
      </plugin>
    </sensor>
  </gazebo>

<!-- Laser Distance Sensor YDLIDAR X4 controller-->
  <gazebo reference="base_scan">
    <sensor type="ray" name="lds_lfcd_sensor">
      <pose>0 0 0 0 0 0</pose>
      <visualize>false</visualize>
      <update_rate>5</update_rate>
      <ray>
        <scan>
          <horizontal>
            <samples>720</samples>
            <resolution>0.5</resolution>
            <min_angle>0.0</min_angle>
            <max_angle>6.28319</max_angle>
          </horizontal>
        </scan>
        <range>
          <min>0.12</min>
          <max>10</max>
          <resolution>0.015</resolution>
        </range>
        <noise>
          <type>gaussian</type>
          <!-- Noise parameters based on published spec for YDLIDAR X4
               is 1.5% at half range 4m (= 60mm, "+-160mm" accuracy at max. range 8m).
               A mean of 0.0m and stddev of 0.020m will put 99.7% of samples
               within 0.16m of the true reading. -->
          <mean>0.0</mean>
          <stddev>0.02</stddev>
        </noise>
      </ray>
      <plugin name="gazebo_ros_lds_lfcd_controller" filename="libgazebo_ros_laser.so">
        <!-- topicName>/gopigo/scan</topicName -->
        <topicName>scan</topicName>
        <frameName>base_scan</frameName>
      </plugin>
    </sensor>
  </gazebo>

</robot>
