<?xml version="1.0" encoding="utf-8"?>
<!-- =================================================================================== -->
<!-- |    This document was autogenerated by xacro from gopigo3.urdf.xacro             | -->
<!-- |    EDITING THIS FILE BY HAND IS NOT RECOMMENDED                                 | -->
<!-- =================================================================================== -->
<robot name="gopigo3">
  <!-- Init colour -->
  <material name="black">
    <color rgba="0.0 0.0 0.0 1.0"/>
  </material>
  <material name="dark">
    <color rgba="0.3 0.3 0.3 1.0"/>
  </material>
  <material name="light_black">
    <color rgba="0.4 0.4 0.4 1.0"/>
  </material>
  <material name="blue">
    <color rgba="0.0 0.0 0.8 1.0"/>
  </material>
  <material name="cyan">
    <color rgba="0.0 1.0 1.0 1.0"/>
  </material>
  <material name="yellow">
    <color rgba="1.0 1.0 0.0 1.0"/>
  </material>
  <material name="green">
    <color rgba="0.0 0.8 0.0 1.0"/>
  </material>
  <material name="grey">
    <color rgba="0.5 0.5 0.5 1.0"/>
  </material>
  <material name="orange">
    <color rgba="1.0 0.423529411765 0.0392156862745 1.0"/>
  </material>
  <material name="brown">
    <color rgba="0.870588235294 0.811764705882 0.764705882353 1.0"/>
  </material>
  <material name="red">
    <color rgba="0.8 0.0 0.0 1.0"/>
  </material>
  <material name="white">
    <color rgba="1.0 1.0 1.0 1.0"/>
  </material>
  <gazebo reference="base_link">
    <material>Gazebo/GreenTransparent</material>
  </gazebo>
  <gazebo reference="name_link">
    <material>Gazebo/Yellow</material>
  </gazebo>
  <gazebo reference="base_scan">
    <material>Gazebo/Blue</material>
  </gazebo>
  <gazebo reference="camera_link">
    <material>Gazebo/Red</material>
  </gazebo>
  <!-- Left wheel mechanical properties -->
  <gazebo reference="wheel_left_link">
    <mu1>0.5</mu1>
    <mu2>0.5</mu2>
    <kp>500000.0</kp>
    <kd>10.0</kd>
    <minDepth>0.001</minDepth>
    <maxVel>0.5</maxVel>
    <fdir1>1 0 0</fdir1>
    <material>Gazebo/FlatBlack</material>
  </gazebo>
  <!-- Right wheel mechanical properties -->
  <gazebo reference="wheel_right_link">
    <mu1>0.5</mu1>
    <mu2>0.5</mu2>
    <kp>500000.0</kp>
    <kd>10.0</kd>
    <minDepth>0.001</minDepth>
    <maxVel>0.5</maxVel>
    <fdir1>1 0 0</fdir1>
    <material>Gazebo/FlatBlack</material>
  </gazebo>
  <!-- Caster back mechanical properties -->
  <gazebo reference="caster_back_link">
    <mu1>0.001</mu1>
    <mu2>0.001</mu2>
    <kp>1000000.0</kp>
    <kd>100.0</kd>
    <minDepth>0.001</minDepth>
    <maxVel>10.0</maxVel>
    <material>Gazebo/FlatBlack</material>
  </gazebo>
  <!-- Differential Drive Controller -->
  <gazebo>
    <plugin filename="libgazebo_ros_diff_drive.so" name="gopigo3_controller">
      <commandTopic>cmd_vel</commandTopic>
      <odometryTopic>odom</odometryTopic>
      <odometryFrame>odom</odometryFrame>
      <odometrySource>world</odometrySource>
      <publishOdomTF>true</publishOdomTF>
      <robotBaseFrame>base_footprint</robotBaseFrame>
      <publishWheelTF>false</publishWheelTF>
      <publishTf>true</publishTf>
      <publishWheelJointState>true</publishWheelJointState>
      <legacyMode>false</legacyMode>
      <updateRate>30</updateRate>
      <leftJoint>wheel_left_joint</leftJoint>
      <rightJoint>wheel_right_joint</rightJoint>
      <wheelSeparation>0.116</wheelSeparation>
      <wheelDiameter>0.066</wheelDiameter>
      <wheelAcceleration>0.5</wheelAcceleration>
      <wheelTorque>1</wheelTorque>
      <rosDebugLevel>na</rosDebugLevel>
    </plugin>
  </gazebo>
  <!-- Laser Distance Sensor YDLIDAR X4 controller-->
  <gazebo reference="base_scan">
    <material>Gazebo/Blue</material>
    <sensor name="lds_lfcd_sensor" type="ray">
      <pose>0 0 0 0 0 0</pose>
      <visualize>false</visualize>
      <update_rate>10</update_rate>
      <ray>
        <scan>
          <horizontal>
            <samples>720</samples>
            <resolution>1</resolution>
            <min_angle>0.0</min_angle>
            <max_angle>6.28319</max_angle>
          </horizontal>
        </scan>
        <range>
          <min>0.120</min>
          <max>10</max>
          <resolution>0.015</resolution>
        </range>
        <noise>
          <type>gaussian</type>
          <!-- Noise parameters based on published spec for YDLIDAR X4
               is 1.5% at half range 4m (= 60mm, "+-160mm" accuracy at max. range 8m).
               A mean of 0.0m and stddev of 0.020m will put 99.7% of samples
               within 0.16m of the true reading. -->
          <mean>0.0</mean>
          <stddev>0.02</stddev>
        </noise>
      </ray>
      <plugin filename="libgazebo_ros_laser.so" name="gazebo_ros_lds_lfcd_controller">
        <topicName>scan</topicName>
        <frameName>base_scan</frameName>
      </plugin>
    </sensor>
  </gazebo>
  <!-- 2D Camera controller -->
  <gazebo reference="camera_link">
    <sensor name="camera1" type="camera">
      <always_on>true</always_on>
      <visualize>false</visualize>
      <camera name="front">
        <horizontal_fov>1.3962634</horizontal_fov>
        <image>
          <width>800</width>
          <height>800</height>
          <format>R8G8B8</format>
        </image>
        <clip>
          <near>0.02</near>
          <far>300</far>
        </clip>
      </camera>
      <plugin filename="libgazebo_ros_camera.so" name="camera_controller">
        <alwaysOn>true</alwaysOn>
        <updateRate>30.0</updateRate>
        <cameraName>gopigo/camera1</cameraName>
        <imageTopicName>image_raw</imageTopicName>
        <cameraInfoTopicName>camera_info</cameraInfoTopicName>
        <frameName>camera_rgb_frame</frameName>
        <hackBaseline>0.07</hackBaseline>
        <distortionK1>0.0</distortionK1>
        <distortionK2>0.0</distortionK2>
        <distortionK3>0.0</distortionK3>
        <distortionT1>0.0</distortionT1>
        <distortionT2>0.0</distortionT2>
      </plugin>
    </sensor>
  </gazebo>
  <!-- ============ 'base_footprint' is the ground link ===================== -->
  <link name="base_footprint"/>

  <!-- ============  'base_link_cad' is the solid model of robot body ====== -->
  <joint name="base_joint" type="fixed">
    <parent link="base_footprint"/>
    <child link="base_link"/>
    <!-- CAD of body of GoPiGo3 has its reference coordinate system at the center of the wheels shaft -->
    <origin rpy="0 0 0" xyz="0 0 0"/>
  </joint>
  <link name="base_link">
    <visual>
      <!-- Decentering of the CAD model coordinate system-->
      <origin rpy="0 0 0" xyz="0 0 0"/>
      <geometry>
        <mesh filename="package://gopigo3_description/meshes/GoPiGo3_Body2.stl" scale="0.0012 0.0012 0.0012"/>
      </geometry>
      <material name="cyan"/>
    </visual>
    <collision>
      <origin rpy="0 0 0" xyz="-0.038 0 0"/>
      <geometry>
        <box size="0.245 0.088 0.02"/>
      </geometry>
    </collision>
    <inertial>
      <origin rpy="0 0 0" xyz="0 0 0"/>
      <mass value="0.534"/>
      <inertia ixx="1.0e-03" ixy="0" ixz="0" iyy="2.0e-03" iyz="0" izz="2.45e-03"/>
    </inertial>
  </link>
  <!-- ============ wheel_left ====================== -->
  <joint name="wheel_left_joint" type="continuous">
    <parent link="base_link"/>
    <child link="wheel_left_link"/>
    <origin rpy="0 0 1.57" xyz="0 0.058 0.0"/>
    <axis xyz="1 0 0"/>
  </joint>
  <link name="wheel_left_link">
    <visual>
      <origin rpy="0 0 0" xyz="-0.22581 -0.200334 -0.033582"/>
      <geometry>
        <mesh filename="package://gopigo3_description/meshes/GoPiGo3_Wheel.stl" scale="0.001158 0.001158 0.001158"/>
      </geometry>
      <material name="black"/>
    </visual>
    <collision>
      <origin rpy="0 1.57 0" xyz="0 0 0"/>
      <geometry>
        <cylinder length="0.026" radius="0.033"/>
      </geometry>
    </collision>
    <inertial>
      <origin xyz="0 0 0"/>
      <mass value="0.032"/>
      <inertia ixx="1.74e-05" ixy="0" ixz="0" iyy="1.05e-05" iyz="0" izz="1.05e-05"/>
    </inertial>
  </link>
  <!-- ============ wheel_right ====================== -->
  <joint name="wheel_right_joint" type="continuous">
    <parent link="base_link"/>
    <child link="wheel_right_link"/>
    <origin rpy="0 0 -1.57" xyz="0 -0.058 0.0"/>
    <axis xyz="-1 0 0"/>
  </joint>
  <link name="wheel_right_link">
    <visual>
      <origin rpy="0 0 0" xyz="-0.22581 -0.200334 -0.033582"/>
      <geometry>
        <mesh filename="package://gopigo3_description/meshes/GoPiGo3_Wheel.stl" scale="0.001158 0.001158 0.001158"/>
      </geometry>
      <material name="black"/>
    </visual>
    <collision>
      <origin rpy="0 1.57 0" xyz="0 0 0"/>
      <geometry>
        <cylinder length="0.026" radius="0.033"/>
      </geometry>
    </collision>
    <inertial>
      <origin xyz="0 0 0"/>
      <mass value="0.032"/>
      <inertia ixx="1.74e-05" ixy="0" ixz="0" iyy="1.05e-05" iyz="0" izz="1.05e-05"/>
    </inertial>
  </link>
  <!-- ============ caster_back ====================== -->
  <joint name="caster_back_joint" type="fixed">
    <parent link="base_link"/>
    <child link="caster_back_link"/>
    <origin rpy="0 0 0" xyz="-0.132 0 -0.04"/>
  </joint>
  <link name="caster_back_link">
    <collision>
      <origin rpy="1.57 0 0" xyz="0 0 0.01"/>
      <geometry>
        <cylinder length="0.009" radius="0.01"/>
      </geometry>
    </collision>
    <!-- <visual>
      <origin xyz="0 0 0.01" rpy="1.57 0 0"/>
      <geometry>
        <cylinder length="0.009" radius="0.01"/>
      </geometry>
    </visual> -->
    <inertial>
      <origin xyz="0 0 0"/>
      <mass value="0.005"/>
      <inertia ixx="0.001" ixy="0.0" ixz="0.0" iyy="0.001" iyz="0.0" izz="0.001"/>
    </inertial>
  </link>
  <!-- YD lidar -->
  <joint name="scan_joint" type="fixed">
    <parent link="base_link"/>
    <child link="base_scan"/>
    <origin rpy="0 0 0" xyz="0 0 0.14"/>
  </joint>
  <link name="base_scan">
    <visual>
      <origin rpy="0 0 3.1416" xyz="0.005 0 0"/>
      <geometry>
        <mesh filename="package://gopigo3_description/meshes/sensors/X4.stl" scale="0.001 0.001 0.001"/>
      </geometry>
      <material name="blue"/>
    </visual>
    <collision>
      <origin rpy="0 0 0" xyz="0 0 0"/>
      <geometry>
        <cylinder length="0.055" radius="0.035"/>
      </geometry>
    </collision>
    <inertial>
      <mass value="0.178"/>
      <inertia ixx="1.10e-04" ixy="-1.56e-04" ixz="-3.12e-04" iyy="1.85e-04" iyz="-2.23e-04" izz="2.21e-04"/>
    </inertial>
  </link>
  <!-- Pi Camera -->
  <link name="camera_link">
    <visual>
      <origin rpy="0 1.57 0" xyz="0 0 0"/>
      <geometry>
        <mesh filename="package://gopigo3_description/meshes/sensors/piCamera.stl" scale="0.00125 0.00125 0.00125"/>
      </geometry>
      <material name="black"/>
    </visual>
    <collision>
      <origin rpy="0 0 0" xyz="0.005 0 0.013"/>
      <geometry>
        <box size="0.015 0.030 0.027"/>
      </geometry>
    </collision>
    <inertial>
      <mass value="0.02"/>
      <inertia ixx="1.10e-04" ixy="0" ixz="0" iyy="1.85e-04" iyz="0" izz="2.21e-04"/>
    </inertial>
  </link>
  <joint name="camera_joint" type="fixed">
    <origin rpy="0 0 0" xyz="0.07 0 0.03"/>
    <parent link="base_link"/>
    <child link="camera_link"/>
  </joint>
  <!-- name link -->
  <link name="name_link">
    <visual>
      <origin rpy="0 0 0" xyz="0 0 0"/>
      <geometry>
        <mesh filename="package://gopigo3_description/meshes/number2.stl" scale="0.0008 0.0008 0.0008"/>
      </geometry>
      <material name="yellow"/>
    </visual>
    <collision>
      <origin rpy="0 0 0" xyz="0 0 0"/>
      <geometry>
        <box size="0.01 0.01 0.002"/>
      </geometry>
    </collision>
    <inertial>
      <mass value="0.2"/>
      <inertia ixx="1.10e-04" ixy="0" ixz="0" iyy="1.85e-04" iyz="0" izz="2.21e-04"/>
    </inertial>
  </link>
  <joint name="name_joint" type="fixed">
    <origin rpy="0 0 0" xyz="-0.115 0 0.057"/>
    <parent link="base_link"/>
    <child link="name_link"/>
  </joint>
</robot>
